Workbook

Sheet Overview
A1: Vakil.app — build tracker
A2: Single-entity case manager for advocates · Expo + NativeWind · Node.js API · Supabase · Plus Jakarta Sans · Tabler icons
A4: Track | B4: Total | C4: Done | D4: In progress | E4: Blocked | F4: % done
A5: Screens: design | B5: =COUNTA(Screens!A5:A54) -> 50 | C5: =COUNTIF(Screens!G5:G54,"Done") -> 1 | D5: =COUNTIF(Screens!G5:G54,"In progress")+COUNTIF(Screens!G5:G54,"In review") -> 0 | E5: =COUNTIF(Screens!G5:G54,"Blocked") -> 0 | F5: =IF(B5=0,0,C5/B5) -> 0.02
A6: Screens: development | B6: =COUNTA(Screens!A5:A54) -> 50 | C6: =COUNTIF(Screens!H5:H54,"Done") -> 0 | D6: =COUNTIF(Screens!H5:H54,"In progress")+COUNTIF(Screens!H5:H54,"In review") -> 1 | E6: =COUNTIF(Screens!H5:H54,"Blocked") -> 0 | F6: =IF(B6=0,0,C6/B6) -> 0
A7: Components: Figma | B7: =COUNTA(Components!A5:A60) -> 56 | C7: =COUNTIF(Components!G5:G60,"Done") -> 0 | D7: =COUNTIF(Components!G5:G60,"In progress")+COUNTIF(Components!G5:G60,"In review") -> 0 | E7: =COUNTIF(Components!G5:G60,"Blocked") -> 0 | F7: =IF(B7=0,0,C7/B7) -> 0
A8: Components: code | B8: =COUNTA(Components!A5:A60) -> 56 | C8: =COUNTIF(Components!H5:H60,"Done") -> 0 | D8: =COUNTIF(Components!H5:H60,"In progress")+COUNTIF(Components!H5:H60,"In review") -> 0 | E8: =COUNTIF(Components!H5:H60,"Blocked") -> 0 | F8: =IF(B8=0,0,C8/B8) -> 0
A9: Requirements: dev | B9: =COUNTA(Requirements!A5:A78) -> 74 | C9: =COUNTIF(Requirements!F5:F78,"Done") -> 0 | D9: =COUNTIF(Requirements!F5:F78,"In progress")+COUNTIF(Requirements!F5:F78,"In review") -> 0 | E9: =COUNTIF(Requirements!F5:F78,"Blocked") -> 0 | F9: =IF(B9=0,0,C9/B9) -> 0
A10: Requirements: QA | B10: =COUNTA(Requirements!A5:A78) -> 74 | C10: =COUNTIF(Requirements!G5:G78,"Done") -> 0 | D10: =COUNTIF(Requirements!G5:G78,"In progress")+COUNTIF(Requirements!G5:G78,"In review") -> 0 | E10: =COUNTIF(Requirements!G5:G78,"Blocked") -> 0 | F10: =IF(B10=0,0,C10/B10) -> 0
A11: API endpoints: dev | B11: =COUNTA(API!A5:A50) -> 46 | C11: =COUNTIF(API!F5:F50,"Done") -> 0 | D11: =COUNTIF(API!F5:F50,"In progress")+COUNTIF(API!F5:F50,"In review") -> 0 | E11: =COUNTIF(API!F5:F50,"Blocked") -> 0 | F11: =IF(B11=0,0,C11/B11) -> 0
A12: Database: migrations | B12: =COUNTA(Database!A5:A39) -> 35 | C12: =COUNTIF(Database!F5:F39,"Done") -> 0 | D12: =COUNTIF(Database!F5:F39,"In progress")+COUNTIF(Database!F5:F39,"In review") -> 0 | E12: =COUNTIF(Database!F5:F39,"Blocked") -> 0 | F12: =IF(B12=0,0,C12/B12) -> 0
A14: How to use
A15: • Update the yellow status columns on each tab using the dropdown (Not started, In progress, In review, Done, Blocked).
A16: • This Overview recalculates automatically from those columns.
A17: • Screens row SCR-01 has example values to show the expected format; reset it when you start.
A18: • Source of truth for detail: the PRD, FRS and User Flow docs.

Sheet Screens
A1: Screen inventory
A2: 50 screens, sheets and dialogs. Yellow columns are yours to update (pick from the dropdown).
A4: ID | B4: Screen | C4: Type | D4: Module | E4: Key components | F4: Priority | G4: Design status | H4: Dev status | I4: Notes
A5: SCR-01 | B5: Splash | C5: Screen | D5: Auth | E5: Logo on grad-glow | F5: P0 | G5: Done | H5: In progress | I5: Example row: logo exported
A6: SCR-02 | B6: Welcome carousel (3 slides) | C6: Screen | D6: Onboarding | E6: Illustration, dots, Gradient button | F6: P0 | G6: Not started | H6: Not started
A7: SCR-03 | B7: Sign in (phone) | C7: Screen | D7: Auth | E7: Phone input, Primary button, email link | F7: P0 | G7: Not started | H7: Not started
A8: SCR-04 | B8: Sign in (email + password) | C8: Screen | D8: Auth | E8: Text fields, Primary button | F8: P0 | G8: Not started | H8: Not started
A9: SCR-05 | B9: OTP verification | C9: Screen | D9: Auth | E9: OTP input, 30 s resend timer | F9: P0 | G9: Not started | H9: Not started
A10: SCR-06 | B10: Profile setup | C10: Screen | D10: Onboarding | E10: Avatar, name, enrolment no., practice areas | F10: P0 | G10: Not started | H10: Not started
A11: SCR-07 | B11: Primary courts setup | C11: Screen | D11: Onboarding | E11: Searchable multi-select, Add court | F11: P0 | G11: Not started | H11: Not started
A12: SCR-08 | B12: Notification permission | C12: Screen | D12: Onboarding | E12: Illustration, Allow / Later | F12: P0 | G12: Not started | H12: Not started
A13: SCR-09 | B13: Home dashboard | C13: Tab | D13: Dashboard | E13: Hero card, stat grid, week strip, today list, quick actions | F13: P0 | G13: Not started | H13: Not started
A14: SCR-10 | B14: Today's hearings | C14: Screen | D14: Dashboard | E14: Grouped by court, hearing cards, Update | F14: P0 | G14: Not started | H14: Not started
A15: SCR-11 | B15: Cases list | C15: Tab | D15: Cases | E15: Search, filter chips, sort, case cards, FAB | F15: P0 | G15: Not started | H15: Not started
A16: SCR-12 | B16: Case filters | C16: Sheet | D16: Cases | E16: Status, type, court, date range, client | F16: P0 | G16: Not started | H16: Not started
A17: SCR-13 | B17: Sort options | C17: Sheet | D17: Cases | E17: Radio list | F17: P0 | G17: Not started | H17: Not started
... A54: SCR-50 | B54: System states | C54: Overlay | D54: Global | E54: Offline banner, error, empty, force update | F54: P0 | G54: Not started | H54: Not started

Sheet Components
A1: UI component library
A2: 56 components. States for all: default, pressed (0.97), focused, disabled (40%), loading; inputs add error. Dark + light.
A4: ID | B4: Group | C4: Component | D4: Variants | E4: Size (dp) | F4: Style notes | G4: Figma status | H4: Code status
A5: CMP-01 | B5: Actions | C5: Button | D5: Primary, Gradient, Secondary, Outline, Ghost, Destructive, Destructive-ghost | E5: sm 36, md 44, lg 52 | F5: rounded-md, button type, icon 20, loading spinner | G5: Not started | H5: Not started
A6: CMP-02 | B6: Actions | C6: Icon button | D6: Filled, Tonal, Ghost, Outline | E6: 32 / 40 / 48 (target 48) | F6: rounded-md or full | G6: Not started | H6: Not started
A7: CMP-03 | B7: Actions | C7: FAB | D7: Circular, Extended, Speed-dial | E7: 56 / 52 | F7: grad-primary, glow, hide on scroll down | G7: Not started | H7: Not started
A8: CMP-04 | B8: Actions | C8: Link / text action | D8: Default, Inline, With chevron | E8: 20 line | F8: primary text | G8: Not started | H8: Not started
A9: CMP-05 | B9: Actions | C9: Quick action tile | D9: Icon + label | E9: 88 x 88 | F9: surface card, 40 dp primary-subtle icon circle | G9: Not started | H9: Not started
A10: CMP-06 | B10: Actions | C10: Swipe actions | D10: Leading, Trailing | E10: row height | F10: 72 dp action width, haptic | G10: Not started | H10: Not started
A11: CMP-07 | B11: Inputs | C11: Text field | D11: Filled, Outline; icons, prefix, suffix | E11: 52 | F11: surface-2 fill, label above, helper/error below | G11: Not started | H11: Not started
A12: CMP-08 | B12: Inputs | C12: Text area | D12: Auto-grow 3-10 lines | E12: min 104 | F12: same as field | G12: Not started | H12: Not started
A13: CMP-09 | B13: Inputs | C13: Search bar | D13: Inline, Expanded, With filter | E13: 44 | F13: rounded-full, 300 ms debounce | G13: Not started | H13: Not started
A14: CMP-10 | B14: Inputs | C14: Select (picker) | D14: Bottom-sheet list, searchable, Add new row | E14: 52 | F14: chevron-down trailing | G14: Not started | H14: Not started
A15: CMP-11 | B15: Inputs | C15: Multi-select | D15: Chips in field, checkbox sheet | E15: 52+ | F15: wrap 2 lines then +N | G15: Not started | H15: Not started
... A60: CMP-56 | B60: Overlays | C60: Loading overlay | D60: Blocking spinner | E60: - | F60: rare | G60: Not started | H60: Not started

Sheet Requirements
A1: Functional requirements
A2: Full detail in the FRS doc. Track build and QA here.
A4: ID | B4: Module | C4: Requirement | D4: Acceptance criteria | E4: Priority | F4: Dev status | G4: QA status | H4: Notes
A5: FR-AUTH-01 | B5: Auth | C5: Sign in with mobile + 6-digit OTP | D5: OTP within 10 s; resend after 30 s; 5 attempts / 15 min | E5: P0 | F5: Not started | G5: Not started
A6: FR-AUTH-02 | B6: Auth | C6: Email + password fallback | D6: Min 8 chars; forgot password link | E6: P0 | F6: Not started | G6: Not started
A7: FR-AUTH-03 | B7: Auth | C7: Persistent session, silent refresh | D7: 30 days; tokens in SecureStore | E7: P0 | F7: Not started | G7: Not started
A8: FR-AUTH-04 | B8: Auth | C8: Route new users to onboarding | D8: Based on onboarded_at | E8: P0 | F8: Not started | G8: Not started
A9: FR-AUTH-05 | B9: Auth | C9: Logout clears tokens, cache, push token | D9: No data reachable after logout | E9: P0 | F9: Not started | G9: Not started
A10: FR-ONB-01 | B10: Onboarding | C10: Profile: name, enrolment no., practice areas, photo | D10: Continue disabled until name valid | E10: P0 | F10: Not started | G10: Not started
A11: FR-ONB-02 | B11: Onboarding | C11: Pick primary courts or add custom | D11: At least 1 court | E11: P0 | F11: Not started | G11: Not started
A12: FR-ONB-03 | B12: Onboarding | C12: Explain then request notification permission | D12: Denied shows banner in Settings | E12: P0 | F12: Not started | G12: Not started
A13: FR-DASH-01 | B13: Dashboard | C13: Hero card with today's hearings | D13: Zero state variant | E13: P0 | F13: Not started | G13: Not started
A14: FR-DASH-02 | B14: Dashboard | C14: Stats: Active, Today, This week, Overdue | D14: Tap opens filtered list | E14: P0 | F14: Not started | G14: Not started
A15: FR-DASH-03 | B15: Dashboard | C15: Week strip with counts | D15: Select day shows hearings | E15: P0 | F15: Not started | G15: Not started
A16: FR-DASH-04 | B16: Dashboard | C16: Quick actions | D16: Open correct flows | E16: P0 | F16: Not started | G16: Not started
... A78: FR-SEC-01 | B78: Security | C78: Biometric / PIN lock | D78: Lock after 1 min background | E78: P1 | F78: Not started | G78: Not started

Sheet API
A1: REST API endpoints
A2: Base URL https://api.vakil.app/api/v1 · Bearer = Supabase access token verified by the Node API
A4: Method | B4: Endpoint | C4: Purpose | D4: FR ref | E4: Auth (Bearer) | F4: Dev status | G4: Tested
A5: POST | B5: /auth/otp/send | C5: Send OTP | D5: FR-AUTH-01 | E5: No | F5: Not started | G5: Not started
A6: POST | B6: /auth/otp/verify | C6: Verify OTP, return session | D6: FR-AUTH-01 | E6: No | F6: Not started | G6: Not started
A7: POST | B7: /auth/email/sign-in | C7: Email sign-in | D7: FR-AUTH-02 | E7: No | F7: Not started | G7: Not started
A8: POST | B8: /auth/refresh | C8: Refresh token | D8: FR-AUTH-03 | E8: No | F8: Not started | G8: Not started
A9: POST | B9: /auth/logout | C9: Logout | D9: FR-AUTH-05 | E9: Yes | F9: Not started | G9: Not started
A10: GET | B10: /me | C10: Get profile | D10: FR-SET-01 | E10: Yes | F10: Not started | G10: Not started
A11: PATCH | B11: /me | C11: Update profile, theme, prefs | D11: FR-ONB-01, FR-SET | E11: Yes | F11: Not started | G11: Not started
A12: POST | B12: /me/onboarding/complete | C12: Finish onboarding, seed lists | D12: FR-ONB-02 | E12: Yes | F12: Not started | G12: Not started
A13: DELETE | B13: /me | C13: Delete account | D13: FR-SET-05 | E13: Yes | F13: Not started | G13: Not started
A14: POST | B14: /me/devices | C14: Register push token | D14: FR-NOTIF-01 | E14: Yes | F14: Not started | G14: Not started
A15: GET | B15: /dashboard | C15: Dashboard payload | D15: FR-DASH | E15: Yes | F15: Not started | G15: Not started
... A50: PATCH/DELETE | B50: /tasks/:id | C50: Edit/delete task (P1) | D50: FR-TASK | E50: Yes | F50: Not started | G50: Not started

Sheet Database
A1: Supabase schema
A2: Postgres. Every table also has id uuid PK, advocate_id, created_at, updated_at.
A4: Table | B4: Column(s) | C4: Type | D4: Constraint / values | E4: Notes | F4: Migration status
A5: advocates | B5: id | C5: uuid | D5: PK, = auth.users.id | E5: The only entity | F5: Not started
A6: advocates | B6: full_name / phone / email | C6: text | F6: Not started
A7: advocates | B7: enrolment_no | C7: text | D7: nullable | E7: Bar Council enrolment | F7: Not started
A8: advocates | B8: practice_areas | C8: text[] | F8: Not started
A9: advocates | B9: theme | C9: text | D9: dark | light | system, default dark | F9: Not started
A10: advocates | B10: notification_prefs | C10: jsonb | E10: evening/morning times, toggles | F10: Not started
A11: advocates | B11: onboarded_at | C11: timestamptz | D11: nullable | F11: Not started
A12: courts | B12: name, short_name, city, district, state | C12: text | E12: Seeded per advocate | F12: Not started
A13: courts | B13: sort_order / is_hidden | C13: int / bool | F13: Not started
A14: case_types | B14: name, sort_order, is_hidden | C14: text / int / bool | E14: Seeded, editable | F14: Not started
A15: clients | B15: full_name, phone, alt_phone, email, address, notes | C15: text | D15: unique (advocate_id, phone) | F15: Not started
A16: cases | B16: title, case_number, case_year, cnr_number | C16: text / int | D16: cnr 16 chars | F16: Not started
A17: cases | B17: case_type_id, court_id | C17: uuid | D17: FK | F17: Not started
A18: cases | B18: court_room, judge_name, filing_date | C18: text / date | F18: Not started
A19: cases | B19: our_side | C19: text | D19: petitioner | respondent | complainant | accused | appellant | other | F19: Not started
A20: cases | B20: petitioner_name, respondent_name, opposite_counsel | C20: text | F20: Not started
A21: cases | B21: stage | C21: text | F21: Not started
A22: cases | B22: status | C22: text | D22: active | reserved | disposed | closed | F22: Not started
A23: cases | B23: disposal_date, disposal_result | C23: date / text | F23: Not started
A24: cases | B24: priority | C24: text | D24: normal | high | urgent | F24: Not started
A25: cases | B25: next_hearing_at, last_hearing_at | C25: date | D25: denormalized, indexed | E25: Maintained by trigger/API | F25: Not started
A26: cases | B26: archived_at, deleted_at | C26: timestamptz | E26: Soft flags | F26: Not started
A27: case_clients | B27: case_id, client_id, role | C27: uuid / text | D27: PK (case_id, client_id) | E27: Many-to-many | F27: Not started
A28: hearings | B28: case_id, hearing_date, hearing_time | C28: uuid / date / time | D28: index (advocate_id, hearing_date) | F28: Not started
A29: hearings | B29: purpose, court_room | C29: text | F29: Not started
A30: hearings | B30: outcome | C30: text | D30: adjourned | heard | arguments_done | evidence | reserved | disposed | not_reached | other | F30: Not started
A31: hearings | B31: outcome_notes, next_hearing_id, completed_at | C31: text / uuid / timestamptz | F31: Not started
A32: notes | B32: case_id, title, body, is_pinned, deleted_at | E32: P1 | F32: Not started
A33: documents | B33: case_id, file_name, category, mime_type, size_bytes, storage_path | E33: P1, bucket case-docs | F33: Not started
A34: fees | B34: case_id, agreed_amount | C34: uuid / numeric(12,2) | D34: one per case | E34: P1 | F34: Not started
A35: payments | B35: case_id, amount, paid_on, mode, note | C35: numeric / date / text | D35: mode: cash | upi | bank | cheque | E35: P1 | F35: Not started
A36: tasks | B36: case_id, title, due_date, completed_at | D36: case_id nullable | E36: P1 | F36: Not started
A37: notifications | B37: type, title, body, deep_link, read_at, sent_at | D37: 60-day retention | F37: Not started
A38: device_tokens | B38: expo_push_token, platform, last_seen_at | C38: text | F38: Not started
A39: ALL TABLES | B39: advocate_id, created_at, updated_at | C39: uuid / timestamptz | D39: RLS: advocate_id = auth.uid() | E39: Every table | F39: Not started

Sheet Design Tokens
A1: Design tokens
A2: Column C/D: dark value / light value for semantic tokens; start / end stops for gradients. Swatches are filled.
A4: Group | B4: Token | C4: Value (dark / start) | D4: Value (light / end) | E4: Notes
A5: Primary | B5: blue-50 | C5: #EEF4FF
A6: Primary | B6: blue-100 | C6: #DCE7FF
A7: Primary | B7: blue-200 | C7: #BCD2FF
A8: Primary | B8: blue-300 | C8: #8EB3FF
A9: Primary | B9: blue-400 | C9: #5B8CFF
A10: Primary | B10: blue-500 | C10: #3366FF | E10: Dark primary
A11: Primary | B11: blue-600 | C11: #2350E6 | E11: Light primary
A12: Primary | B12: blue-700 | C12: #1C3FC0
A13: Primary | B13: blue-800 | C13: #1B3699
A14: Primary | B14: blue-900 | C14: #1B3279
A15: Primary | B15: blue-950 | C15: #121F4A
A16: Neutral | B16: ink-0 | C16: #FFFFFF
A17: Neutral | B17: ink-50 | C17: #F6F8FC
A18: Neutral | B18: ink-100 | C18: #EDF1F8
A19: Neutral | B19: ink-200 | C19: #DCE3EF
A20: Neutral | B20: ink-300 | C20: #BCC7DA
A21: Neutral | B21: ink-400 | C21: #8C9AB3
A22: Neutral | B22: ink-500 | C22: #64728C
A23: Neutral | B23: ink-600 | C23: #475570
... A27: Neutral | B27: ink-950 | C27: #0A101D
A28: Semantic | B28: bg | C28: #0A101D | D28: #F6F8FC
A29: Semantic | B29: surface | C29: #121A2B | D29: #FFFFFF
A30: Semantic | B30: surface-2 | C30: #1C2538 | D30: #EDF1F8
A31: Semantic | B31: border | C31: #2E3A52 | D31: #DCE3EF
A32: Semantic | B32: border-strong | C32: #475570 | D32: #BCC7DA
A33: Semantic | B33: text | C33: #F6F8FC | D33: #121A2B
A34: Semantic | B34: text-2 | C34: #BCC7DA | D34: #475570
A35: Semantic | B35: text-3 | C35: #8C9AB3 | D35: #64728C
A36: Semantic | B36: primary | C36: #3366FF | D36: #2350E6
A37: Semantic | B37: primary-pressed | C37: #2350E6 | D37: #1C3FC0
A38: Semantic | B38: primary-subtle | C38: #121F4A | D38: #EEF4FF
A39: Status | B39: success | C39: #22C55E | E39: bg dark #0F2A1C / light #E8F8EE
A40: Status | B40: warning | C40: #F59E0B | E40: bg dark #2E2209 / light #FEF4E2
A41: Status | B41: error | C41: #EF4444 | E41: bg dark #2F1316 / light #FDECEC
A42: Status | B42: info | C42: #0EA5E9 | E42: bg dark #0B2533 / light #E6F6FD
A43: Status | B43: adjourned | C43: #8B5CF6 | E43: bg dark #221A3D / light #F1ECFE
A44: Gradient | B44: grad-primary | C44: #3366FF | D44: #6A4CFF | E44: 135 deg
...
